<sdf version='1.6'>
  <world name='default'>
    <light name='sun' type='directional'>
      <cast_shadows>1</cast_shadows>
      <pose frame=''>0 0 10 0 -0 0</pose>
      <diffuse>0.8 0.8 0.8 1</diffuse>
      <specular>0.1 0.1 0.1 1</specular>
      <attenuation>
        <range>1000</range>
        <constant>0.9</constant>
        <linear>0.01</linear>
        <quadratic>0.001</quadratic>
      </attenuation>
      <direction>-0.5 0.5 -1</direction>
    </light>
    <model name='ground_plane'>
      <static>1</static>
      <link name='link'>
        <collision name='collision'>
          <geometry>
            <plane>
              <normal>0 0 1</normal>
              <size>100 100</size>
            </plane>
          </geometry>
          <surface>
            <friction>
              <ode>
                <mu>100</mu>
                <mu2>50</mu2>
              </ode>
              <torsional>
                <ode/>
              </torsional>
            </friction>
            <contact>
              <ode/>
            </contact>
            <bounce/>
          </surface>
          <max_contacts>10</max_contacts>
        </collision>
        <visual name='visual'>
          <cast_shadows>0</cast_shadows>
          <geometry>
            <plane>
              <normal>0 0 1</normal>
              <size>100 100</size>
            </plane>
          </geometry>
          <material>
            <script>
              <uri>file://media/materials/scripts/gazebo.material</uri>
              <name>Gazebo/Grey</name>
            </script>
          </material>
        </visual>
        <self_collide>0</self_collide>
        <kinematic>0</kinematic>
        <gravity>1</gravity>
      </link>
    </model>
    <gravity>0 0 -9.8</gravity>
    <magnetic_field>6e-06 2.3e-05 -4.2e-05</magnetic_field>
    <atmosphere type='adiabatic'/>
    <physics name='default_physics' default='0' type='ode'>
      <max_step_size>0.001</max_step_size>
      <real_time_factor>1</real_time_factor>
      <real_time_update_rate>1000</real_time_update_rate>
    </physics>
    <scene>
      <ambient>0.4 0.4 0.4 1</ambient>
      <background>0.7 0.7 0.7 1</background>
      <shadows>1</shadows>
    </scene>
    <spherical_coordinates>
      <surface_model>EARTH_WGS84</surface_model>
      <latitude_deg>0</latitude_deg>
      <longitude_deg>0</longitude_deg>
      <elevation>0</elevation>
      <heading_deg>0</heading_deg>
    </spherical_coordinates>
    <model name='rbcar'>
      <link name='base_footprint'>
        <pose frame=''>0 0 0 0 -0 0</pose>
        <inertial>
          <pose frame=''>-0.707545 0 -0.171155 0 -0 0</pose>
          <mass>0.27101</mass>
          <inertia>
            <ixx>0.000613278</ixx>
            <ixy>0</ixy>
            <ixz>7.47207e-05</ixz>
            <iyy>0.00053719</iyy>
            <iyz>0</iyz>
            <izz>0.000285912</izz>
          </inertia>
        </inertial>
        <collision name='base_footprint_fixed_joint_lump__base_link_collision'>
          <pose frame=''>-1.0605 0 -0.173 0 -0 0</pose>
          <geometry>
            <box>
              <size>0.707 0.05 0.05</size>
            </box>
          </geometry>
          <surface>
            <contact>
              <ode/>
            </contact>
            <friction>
              <ode/>
              <torsional>
                <ode/>
              </torsional>
            </friction>
            <bounce/>
          </surface>
          <max_contacts>10</max_contacts>
        </collision>
        <collision name='base_footprint_fixed_joint_lump__gps_base_link_collision_1'>
          <pose frame=''>-0.857 0 0.327 0 -0 0</pose>
          <geometry>
            <mesh>
              <scale>1 1 1</scale>
              <uri>/opt/ros/kinetic/share/robotnik_sensors/meshes/antenna_3GO16.stl</uri>
            </mesh>
          </geometry>
          <surface>
            <contact>
              <ode/>
            </contact>
            <friction>
              <ode/>
              <torsional>
                <ode/>
              </torsional>
            </friction>
            <bounce/>
          </surface>
          <max_contacts>10</max_contacts>
        </collision>
        <visual name='base_footprint_visual'>
          <pose frame=''>0 0 0 0 -0 0</pose>
          <geometry>
            <box>
              <size>0.001 0.001 0.001</size>
            </box>
          </geometry>
        </visual>
        <visual name='base_footprint_fixed_joint_lump__base_link_visual_1'>
          <pose frame=''>-1.0605 0 -0.173 0 -0 0</pose>
          <geometry>
            <box>
              <size>0.707 0.05 0.05</size>
            </box>
          </geometry>
          <material>
            <script>
              <name>Gazebo/Blue</name>
              <uri>file://media/materials/scripts/gazebo.material</uri>
            </script>
          </material>
        </visual>
        <visual name='base_footprint_fixed_joint_lump__gps_base_link_visual_2'>
          <pose frame=''>-0.857 0 0.327 0 -0 0</pose>
          <geometry>
            <mesh>
              <scale>1 1 1</scale>
              <uri>/opt/ros/kinetic/share/robotnik_sensors/meshes/antenna_3GO16.stl</uri>
            </mesh>
          </geometry>
          <material>
            <script>
              <name>Gazebo/White</name>
              <uri>file://media/materials/scripts/gazebo.material</uri>
            </script>
          </material>
        </visual>
        <visual name='base_footprint_fixed_joint_lump__hokuyo_base_link_visual_3'>
          <pose frame=''>-0.485 0 -0.17 0 -0 0</pose>
          <geometry>
            <mesh>
              <scale>1 1 1</scale>
              <uri>/opt/ros/kinetic/share/robotnik_sensors/meshes/hokuyo_utm_30lx.dae</uri>
            </mesh>
          </geometry>
        </visual>
        <velocity_decay/>
        <velocity_decay/>
        <gravity>1</gravity>
        <gravity>1</gravity>
        <velocity_decay/>
        <self_collide>0</self_collide>
        <sensor name='hokuyo_sensor' type='ray'>
          <visualize>0</visualize>
          <update_rate>30</update_rate>
          <ray>
            <scan>
              <horizontal>
                <samples>1081</samples>
                <resolution>1</resolution>
                <min_angle>-1.57</min_angle>
                <max_angle>1.57</max_angle>
              </horizontal>
              <vertical>
                <samples>1</samples>
                <min_angle>0</min_angle>
                <max_angle>0</max_angle>
              </vertical>
            </scan>
            <range>
              <min>0.1</min>
              <max>30</max>
              <resolution>0.01</resolution>
            </range>
            <noise>
              <type>gaussian</type>
              <mean>0</mean>
              <stddev>0.01</stddev>
            </noise>
          </ray>
          <plugin name='hokuyo_controller' filename='libgazebo_ros_laser.so'>
            <topicName>front_laser/scan</topicName>
            <frameName>/hokuyo_link</frameName>
            <robotNamespace>/</robotNamespace>
          </plugin>
          <pose frame=''>-0.485 0 -0.115 0 -0 0</pose>
        </sensor>
        <kinematic>0</kinematic>
      </link>
      <link name='FL_upright'>
        <pose frame=''>-0.707 0.1525 -0.173 0 -0 0</pose>
        <inertial>
          <pose frame=''>0 0 0 0 -0 0</pose>
          <mass>0.27</mass>
          <inertia>
            <ixx>0.0002632</ixx>
            <ixy>0</ixy>
            <ixz>0</ixz>
            <iyy>0.0002632</iyy>
            <iyz>0</iyz>
            <izz>0.000162</izz>
          </inertia>
        </inertial>
        <visual name='FL_upright_visual'>
          <pose frame=''>0 0 0 0 -0 0</pose>
          <geometry>
            <box>
              <size>0.1 0.05 0.15</size>
            </box>
          </geometry>
        </visual>
        <self_collide>0</self_collide>
        <kinematic>0</kinematic>
        <gravity>1</gravity>
      </link>
      <joint name='FL_upright_joint' type='revolute'>
        <child>FL_upright</child>
        <parent>base_footprint</parent>
        <axis>
          <xyz>0 0 1</xyz>
          <limit>
            <lower>-0.5</lower>
            <upper>0.5</upper>
            <effort>100</effort>
            <velocity>10</velocity>
          </limit>
          <dynamics>
            <spring_reference>0</spring_reference>
            <spring_stiffness>0</spring_stiffness>
          </dynamics>
          <use_parent_model_frame>1</use_parent_model_frame>
        </axis>
      </joint>
      <link name='FL_wheel'>
        <pose frame=''>-0.707 0.225 -0.173 0 -0 0</pose>
        <inertial>
          <pose frame=''>0 0 0 0 -0 0</pose>
          <mass>0.27</mass>
          <inertia>
            <ixx>0.0002632</ixx>
            <ixy>0</ixy>
            <ixz>0</ixz>
            <iyy>0.0002632</iyy>
            <iyz>0</iyz>
            <izz>0.000162</izz>
          </inertia>
        </inertial>
        <collision name='FL_wheel_collision'>
          <pose frame=''>0 0 0 1.5708 -0 0</pose>
          <geometry>
            <cylinder>
              <length>0.122</length>
              <radius>0.173</radius>
            </cylinder>
          </geometry>
          <surface>
            <contact>
              <ode/>
            </contact>
            <friction>
              <ode/>
              <torsional>
                <ode/>
              </torsional>
            </friction>
            <bounce/>
          </surface>
          <max_contacts>10</max_contacts>
        </collision>
        <visual name='FL_wheel_visual'>
          <pose frame=''>0 0 0 0 -0 1.5708</pose>
          <geometry>
            <mesh>
              <scale>1 1 1</scale>
              <uri>/home/toor/catkin_ws/src/quad.git/quad_description/meshes/Tyre_13x5-6.STL</uri>
            </mesh>
          </geometry>
          <material>
            <script>
              <name>Gazebo/Black</name>
              <uri>file://media/materials/scripts/gazebo.material</uri>
            </script>
          </material>
        </visual>
        <gravity>1</gravity>
        <velocity_decay/>
        <self_collide>0</self_collide>
        <kinematic>0</kinematic>
      </link>
      <joint name='FL_wheel_joint' type='revolute'>
        <child>FL_wheel</child>
        <parent>FL_upright</parent>
        <axis>
          <xyz>0 1 0</xyz>
          <limit>
            <lower>-1e+16</lower>
            <upper>1e+16</upper>
          </limit>
          <dynamics>
            <spring_reference>0</spring_reference>
            <spring_stiffness>0</spring_stiffness>
          </dynamics>
          <use_parent_model_frame>1</use_parent_model_frame>
        </axis>
      </joint>
      <link name='FR_upright'>
        <pose frame=''>-0.707 -0.1525 -0.173 0 -0 0</pose>
        <inertial>
          <pose frame=''>0 0 0 0 -0 0</pose>
          <mass>0.27</mass>
          <inertia>
            <ixx>0.0002632</ixx>
            <ixy>0</ixy>
            <ixz>0</ixz>
            <iyy>0.0002632</iyy>
            <iyz>0</iyz>
            <izz>0.000162</izz>
          </inertia>
        </inertial>
        <visual name='FR_upright_visual'>
          <pose frame=''>0 0 0 0 -0 0</pose>
          <geometry>
            <box>
              <size>0.1 0.05 0.15</size>
            </box>
          </geometry>
        </visual>
        <self_collide>0</self_collide>
        <kinematic>0</kinematic>
        <gravity>1</gravity>
      </link>
      <joint name='FR_upright_joint' type='revolute'>
        <child>FR_upright</child>
        <parent>base_footprint</parent>
        <axis>
          <xyz>0 0 1</xyz>
          <limit>
            <lower>-0.5</lower>
            <upper>0.5</upper>
            <effort>100</effort>
            <velocity>10</velocity>
          </limit>
          <dynamics>
            <spring_reference>0</spring_reference>
            <spring_stiffness>0</spring_stiffness>
          </dynamics>
          <use_parent_model_frame>1</use_parent_model_frame>
        </axis>
      </joint>
      <link name='FR_wheel'>
        <pose frame=''>-0.707 -0.225 -0.173 0 -0 0</pose>
        <inertial>
          <pose frame=''>0 0 0 0 -0 0</pose>
          <mass>0.27</mass>
          <inertia>
            <ixx>0.0002632</ixx>
            <ixy>0</ixy>
            <ixz>0</ixz>
            <iyy>0.0002632</iyy>
            <iyz>0</iyz>
            <izz>0.000162</izz>
          </inertia>
        </inertial>
        <collision name='FR_wheel_collision'>
          <pose frame=''>0 0 0 1.5708 -0 0</pose>
          <geometry>
            <cylinder>
              <length>0.122</length>
              <radius>0.173</radius>
            </cylinder>
          </geometry>
          <surface>
            <contact>
              <ode/>
            </contact>
            <friction>
              <ode/>
              <torsional>
                <ode/>
              </torsional>
            </friction>
            <bounce/>
          </surface>
          <max_contacts>10</max_contacts>
        </collision>
        <visual name='FR_wheel_visual'>
          <pose frame=''>0 0 0 0 -0 1.5708</pose>
          <geometry>
            <mesh>
              <scale>1 1 1</scale>
              <uri>/home/toor/catkin_ws/src/quad.git/quad_description/meshes/Tyre_13x5-6.STL</uri>
            </mesh>
          </geometry>
          <material>
            <script>
              <name>Gazebo/Black</name>
              <uri>file://media/materials/scripts/gazebo.material</uri>
            </script>
          </material>
        </visual>
        <gravity>1</gravity>
        <velocity_decay/>
        <self_collide>0</self_collide>
        <kinematic>0</kinematic>
      </link>
      <joint name='FR_wheel_joint' type='revolute'>
        <child>FR_wheel</child>
        <parent>FR_upright</parent>
        <axis>
          <xyz>0 1 0</xyz>
          <limit>
            <lower>-1e+16</lower>
            <upper>1e+16</upper>
          </limit>
          <dynamics>
            <spring_reference>0</spring_reference>
            <spring_stiffness>0</spring_stiffness>
          </dynamics>
          <use_parent_model_frame>1</use_parent_model_frame>
        </axis>
      </joint>
      <link name='RL_wheel'>
        <pose frame=''>-1.414 0.24 -0.173 0 -0 0</pose>
        <inertial>
          <pose frame=''>0 0 0 0 -0 0</pose>
          <mass>0.27</mass>
          <inertia>
            <ixx>0.0002632</ixx>
            <ixy>0</ixy>
            <ixz>0</ixz>
            <iyy>0.0002632</iyy>
            <iyz>0</iyz>
            <izz>0.000162</izz>
          </inertia>
        </inertial>
        <collision name='RL_wheel_collision'>
          <pose frame=''>0 0 0 1.5708 -0 0</pose>
          <geometry>
            <cylinder>
              <length>0.122</length>
              <radius>0.173</radius>
            </cylinder>
          </geometry>
          <surface>
            <contact>
              <ode/>
            </contact>
            <friction>
              <ode/>
              <torsional>
                <ode/>
              </torsional>
            </friction>
            <bounce/>
          </surface>
          <max_contacts>10</max_contacts>
        </collision>
        <visual name='RL_wheel_visual'>
          <pose frame=''>0 0 0 0 -0 1.5708</pose>
          <geometry>
            <mesh>
              <scale>1 1 1</scale>
              <uri>/home/toor/catkin_ws/src/quad.git/quad_description/meshes/Tyre_13x5-6.STL</uri>
            </mesh>
          </geometry>
          <material>
            <script>
              <name>Gazebo/Black</name>
              <uri>file://media/materials/scripts/gazebo.material</uri>
            </script>
          </material>
        </visual>
        <gravity>1</gravity>
        <velocity_decay/>
        <self_collide>0</self_collide>
        <kinematic>0</kinematic>
      </link>
      <joint name='RL_wheel_joint' type='revolute'>
        <child>RL_wheel</child>
        <parent>base_footprint</parent>
        <axis>
          <xyz>0 1 0</xyz>
          <limit>
            <lower>-1e+16</lower>
            <upper>1e+16</upper>
          </limit>
          <dynamics>
            <spring_reference>0</spring_reference>
            <spring_stiffness>0</spring_stiffness>
          </dynamics>
          <use_parent_model_frame>1</use_parent_model_frame>
        </axis>
      </joint>
      <link name='RR_wheel'>
        <pose frame=''>-1.414 -0.24 -0.173 0 -0 0</pose>
        <inertial>
          <pose frame=''>0 0 0 0 -0 0</pose>
          <mass>0.27</mass>
          <inertia>
            <ixx>0.0002632</ixx>
            <ixy>0</ixy>
            <ixz>0</ixz>
            <iyy>0.0002632</iyy>
            <iyz>0</iyz>
            <izz>0.000162</izz>
          </inertia>
        </inertial>
        <collision name='RR_wheel_collision'>
          <pose frame=''>0 0 0 1.5708 -0 0</pose>
          <geometry>
            <cylinder>
              <length>0.122</length>
              <radius>0.173</radius>
            </cylinder>
          </geometry>
          <surface>
            <contact>
              <ode/>
            </contact>
            <friction>
              <ode/>
              <torsional>
                <ode/>
              </torsional>
            </friction>
            <bounce/>
          </surface>
          <max_contacts>10</max_contacts>
        </collision>
        <visual name='RR_wheel_visual'>
          <pose frame=''>0 0 0 0 -0 1.5708</pose>
          <geometry>
            <mesh>
              <scale>1 1 1</scale>
              <uri>/home/toor/catkin_ws/src/quad.git/quad_description/meshes/Tyre_13x5-6.STL</uri>
            </mesh>
          </geometry>
          <material>
            <script>
              <name>Gazebo/Black</name>
              <uri>file://media/materials/scripts/gazebo.material</uri>
            </script>
          </material>
        </visual>
        <gravity>1</gravity>
        <velocity_decay/>
        <self_collide>0</self_collide>
        <kinematic>0</kinematic>
      </link>
      <joint name='RR_wheel_joint' type='revolute'>
        <child>RR_wheel</child>
        <parent>base_footprint</parent>
        <axis>
          <xyz>0 1 0</xyz>
          <limit>
            <lower>-1e+16</lower>
            <upper>1e+16</upper>
          </limit>
          <dynamics>
            <spring_reference>0</spring_reference>
            <spring_stiffness>0</spring_stiffness>
          </dynamics>
          <use_parent_model_frame>1</use_parent_model_frame>
        </axis>
      </joint>
      <plugin name='gazebo_ros_control' filename='libgazebo_ros_control.so'>
        <robotNamespace>/quad</robotNamespace>
      </plugin>
      <static>0</static>
      <plugin name='gps_controller' filename='libhector_gazebo_ros_gps.so'>
        <alwaysOn>1</alwaysOn>
        <updateRate>5</updateRate>
        <frameId>/gps_base_link</frameId>
        <topicName>fix</topicName>
        <referenceLatitude>39.5080331</referenceLatitude>
        <referenceLongitude>-0.4619816</referenceLongitude>
        <referenceHeading>90</referenceHeading>
        <velocityTopicName>fix_velocity</velocityTopicName>
        <drift>0.0 0.0 0.0</drift>
        <gaussianNoise>0.1 0.1 0.1</gaussianNoise>
        <velocityDrift>0.00001 0.00001 0.00001</velocityDrift>
        <velocityGaussianNoise>0.00001 0.00001 0.00001</velocityGaussianNoise>
        <robotNamespace>/</robotNamespace>
        <bodyName>base_footprint</bodyName>
        <xyzOffset>0.857 0 -0.327</xyzOffset>
        <rpyOffset>0 -0 0</rpyOffset>
      </plugin>
      <pose frame=''>0 0 1 0 -0 0</pose>
    </model>
    <model name='willowgarage'>
      <static>1</static>
      <pose frame=''>-8.47014 2.36766 0 0 -0 0</pose>
      <link name='walls'>
        <collision name='collision'>
          <geometry>
            <mesh>
              <uri>model://willowgarage/meshes/willowgarage_collision.dae</uri>
              <scale>1 1 1</scale>
            </mesh>
          </geometry>
          <max_contacts>10</max_contacts>
          <surface>
            <contact>
              <ode/>
            </contact>
            <bounce/>
            <friction>
              <torsional>
                <ode/>
              </torsional>
              <ode/>
            </friction>
          </surface>
        </collision>
        <visual name='visual'>
          <geometry>
            <mesh>
              <uri>model://willowgarage/meshes/willowgarage_visual.dae</uri>
              <scale>1 1 1</scale>
            </mesh>
          </geometry>
          <cast_shadows>0</cast_shadows>
        </visual>
        <self_collide>0</self_collide>
        <kinematic>0</kinematic>
        <gravity>1</gravity>
      </link>
    </model>
    <state world_name='default'>
      <sim_time>31 615000000</sim_time>
      <real_time>61 963517615</real_time>
      <wall_time>1540237172 133154905</wall_time>
      <iterations>31615</iterations>
      <model name='ground_plane'>
        <pose frame=''>0 0 0 0 -0 0</pose>
        <scale>1 1 1</scale>
        <link name='link'>
          <pose frame=''>0 0 0 0 -0 0</pose>
          <velocity>0 0 0 0 -0 0</velocity>
          <acceleration>0 0 0 0 -0 0</acceleration>
          <wrench>0 0 0 0 -0 0</wrench>
        </link>
      </model>
      <model name='rbcar'>
        <pose frame=''>2.04614 -0.073558 0.346004 1e-05 -7e-06 -0.003258</pose>
        <scale>1 1 1</scale>
        <link name='FL_upright'>
          <pose frame=''>1.33964 0.081246 0.172998 2.8e-05 -2e-06 -0.00291</pose>
          <velocity>-3e-06 0.000543 0.000712 -0.006699 -0.008348 0.002269</velocity>
          <acceleration>-0.272658 0.92455 0.972418 -0.444049 -0.796279 -0.623221</acceleration>
          <wrench>-0.073618 0.249628 0.262553 0 -0 0</wrench>
        </link>
        <link name='FL_wheel'>
          <pose frame=''>1.33985 0.153746 0.173 -1.3e-05 -0.384394 -0.002894</pose>
          <velocity>-0.000255 0.00057 0.000537 -0.003287 -0.001489 0.000185</velocity>
          <acceleration>-0.539478 0.959777 0.688463 3.07332 0.165171 -1.27006</acceleration>
          <wrench>-0.145659 0.25914 0.185885 0 -0 0</wrench>
        </link>
        <link name='FR_upright'>
          <pose frame=''>1.33864 -0.223752 0.172999 -2.7e-05 -8e-06 -0.003494</pose>
          <velocity>0.000134 0.000528 0.000469 0.000903 -0.011628 -0.010142</velocity>
          <acceleration>-0.029357 0.89502 0.687551 2.86693 0.651807 1.81421</acceleration>
          <wrench>-0.007927 0.241655 0.185639 0 -0 0</wrench>
        </link>
        <link name='FR_wheel'>
          <pose frame=''>1.33839 -0.296251 0.173 9e-06 -0.419377 -0.003512</pose>
          <velocity>-0.000598 0.000506 0.000355 -0.003013 -0.007225 -0.010492</velocity>
          <acceleration>-0.802791 0.848952 0.450917 -0.536692 -0.807063 0.213591</acceleration>
          <wrench>-0.216753 0.229217 0.121748 0 -0 0</wrench>
        </link>
        <link name='RL_wheel'>
          <pose frame=''>0.632931 0.171055 0.172991 -1e-06 -0.530539 -0.003261</pose>
          <velocity>0.000209 0.000838 -0.008789 0.002591 -0.013906 -0.001005</velocity>
          <acceleration>-0.165517 0.443809 -8.9617 2.22051 -0.455397 2.87528</acceleration>
          <wrench>-0.04469 0.119828 -2.41966 0 -0 0</wrench>
        </link>
        <link name='RR_wheel'>
          <pose frame=''>0.631363 -0.308937 0.172991 -0 -0.563094 -0.003268</pose>
          <velocity>9.1e-05 -0.000449 -0.009481 0.002157 -0.014929 -0.001055</velocity>
          <acceleration>-0.184242 -0.5916 -9.98552 0.19578 0.203706 2.92835</acceleration>
          <wrench>-0.049745 -0.159732 -2.69609 0 -0 0</wrench>
        </link>
        <link name='base_footprint'>
          <pose frame=''>2.04614 -0.073558 0.346004 1e-05 -7e-06 -0.003258</pose>
          <velocity>-0.001751 0.002148 0.008234 -0.002463 -0.010741 0.001679</velocity>
          <acceleration>-0.201327 0.91816 0.82879 -0.384657 1.49375 -1.18721</acceleration>
          <wrench>-0.054562 0.24883 0.22461 0 -0 0</wrench>
        </link>
      </model>
      <model name='willowgarage'>
        <pose frame=''>-26.758 -11.8718 0 0 -0 0</pose>
        <scale>1 1 1</scale>
        <link name='walls'>
          <pose frame=''>-26.758 -11.8718 0 0 -0 0</pose>
          <velocity>0 0 0 0 -0 0</velocity>
          <acceleration>0 0 0 0 -0 0</acceleration>
          <wrench>0 0 0 0 -0 0</wrench>
        </link>
      </model>
      <light name='sun'>
        <pose frame=''>0 0 10 0 -0 0</pose>
      </light>
    </state>
    <gui fullscreen='0'>
      <camera name='user_camera'>
        <pose frame=''>29.6982 -14.161 12.8075 0 0.275643 2.35619</pose>
        <view_controller>orbit</view_controller>
        <projection_type>perspective</projection_type>
      </camera>
    </gui>
  </world>
</sdf>
