<?xml version="1.0" ?>
<!-- =================================================================================== -->
<!-- |    This document was autogenerated by xacro from quad.xacro                     | -->
<!-- |    EDITING THIS FILE BY HAND IS NOT RECOMMENDED                                 | -->
<!-- =================================================================================== -->
<robot name="quad" xmlns:xacro="http://www.ros.org/wiki/xacro">
  <!--  -->
  xacro:include filename=&quot;/opt/ros/kinetic/share/hector_sensors_description/urdf/hokuyo_utm30lx.urdf.xacro&quot;/--&gt;
	
  <!-- This file unifies all sensors that can be used on simulation, defined as xacro:macros -->
  <material name="aluminum">
    <color rgba="0.5 0.5 0.5 1"/>
  </material>
  <!--xacro:include filename="$(find hector_sensors_description)/urdf/generic_camera.urdf.xacro"/-->
  <!-- Physical Material Macros -->
  <material name="Red">
    <color rgba="1.0 0 0 1.0"/>
  </material>
  <material name="Green">
    <color rgba="0 1.0 0 1.0"/>
  </material>
  <material name="Blue">
    <color rgba="0 0 1.0 0.5"/>
  </material>
  <material name="Black">
    <color rgba="0 0 0 1.0"/>
  </material>
  <material name="Aqua">
    <color rgba="0 255 255 1.0"/>
  </material>
  <gazebo>
    <plugin filename="libgazebo_ros_control.so" name="gazebo_ros_control">
      <robotNamespace>/quad</robotNamespace>
    </plugin>
  </gazebo>
  <link name="base_footprint">
    <visual>
      <origin rpy="0 0 0" xyz="0 0 0"/>
      <geometry>
        <box size="0.001 0.001 0.001"/>
      </geometry>
    </visual>
  </link>
  <joint name="base_footprint_joint" type="fixed">
    <origin rpy="0 0 0" xyz="-0.707 0 -0.173"/>
    <!-- height is the clearance -->
    <parent link="base_footprint"/>
    <child link="base_link"/>
  </joint>
  <!-- base_link must have geometry so that its axes can be displayed in rviz. -->
  <!-- Chassis -->
  <link name="base_link">
    <inertial>
      <mass value="0.270"/>
      <origin rpy="0 0 0" xyz="0 0 0"/>
      <inertia ixx="2.632e-4" ixy="0" ixz="0" iyy="2.632e-4" iyz="0" izz="1.62e-4"/>
    </inertial>
    <visual>
      <origin rpy="0 0 0" xyz="-0.3535 0 0"/>
      <geometry>
        <box size="0.707 0.05 0.05"/>
      </geometry>
      <material name="Blue"/>
    </visual>
    <collision>
      <origin rpy="0 0 0" xyz="-0.3535 0 0"/>
      <geometry>
        <box size="0.707 0.05 0.05"/>
      </geometry>
    </collision>
  </link>
  <gazebo reference="base_link">
    <material>Gazebo/Blue</material>
  </gazebo>
  <!-- Base footprint is on the ground under the robot -->
  <!--link name="base_footprint"/>
	 <joint name="base_footprint_joint" type="fixed">
	  <origin xyz="${-wheelbase} 0 ${-wheelRadius}" rpy="0 0 0" />
	  <parent link="base_link" />
	  <child link="base_footprint" />
	 </joint-->
  <!-- IMU -->
  <link name="imu_link"/>
  <joint name="imu_joint" type="fixed">
    <origin rpy="0 0 0" xyz="-0.3535 0 0"/>
    <parent link="base_link"/>
    <child link="imu_link"/>
  </joint>
  <!-- Camera -->
  <link name="camera_link"/>
  <joint name="camera_joint" type="fixed">
    <origin rpy="0 0 0" xyz="0 0 0.2"/>
    <parent link="base_link"/>
    <child link="camera_link"/>
  </joint>
  <joint name="RL_wheel_joint" type="continuous">
    <axis xyz="0 1 0"/>
    <parent link="base_link"/>
    <child link="RL_wheel"/>
    <origin rpy="0 0 0" xyz="-0.707 0.24 0"/>
  </joint>
  <link name="RL_wheel">
    <inertial>
      <mass value="0.270"/>
      <origin rpy="0 0 0" xyz="0 0 0"/>
      <inertia ixx="2.632e-4" ixy="0" ixz="0" iyy="2.632e-4" iyz="0" izz="1.62e-4"/>
    </inertial>
    <visual>
      <origin rpy="0 0 1.57079633" xyz="0 0 0"/>
      <geometry>
        <mesh filename="package://quad_description/meshes/Tyre_13x5-6.STL"/>
      </geometry>
      <material name="Black"/>
    </visual>
    <collision>
      <origin rpy="1.57079633 0 0" xyz="0 0 0"/>
      <geometry>
        <cylinder length="0.122" radius="0.173"/>
      </geometry>
    </collision>
  </link>
  <gazebo reference="RL_wheel">
    <material>Gazebo/Black</material>
  </gazebo>
  <joint name="RR_wheel_joint" type="continuous">
    <axis xyz="0 1 0"/>
    <parent link="base_link"/>
    <child link="RR_wheel"/>
    <origin rpy="0 0 0" xyz="-0.707 -0.24 0"/>
  </joint>
  <link name="RR_wheel">
    <inertial>
      <mass value="0.270"/>
      <origin rpy="0 0 0" xyz="0 0 0"/>
      <inertia ixx="2.632e-4" ixy="0" ixz="0" iyy="2.632e-4" iyz="0" izz="1.62e-4"/>
    </inertial>
    <visual>
      <origin rpy="0 0 1.57079633" xyz="0 0 0"/>
      <geometry>
        <mesh filename="package://quad_description/meshes/Tyre_13x5-6.STL"/>
      </geometry>
      <material name="Black"/>
    </visual>
    <collision>
      <origin rpy="1.57079633 0 0" xyz="0 0 0"/>
      <geometry>
        <cylinder length="0.122" radius="0.173"/>
      </geometry>
    </collision>
  </link>
  <gazebo reference="RR_wheel">
    <material>Gazebo/Black</material>
  </gazebo>
  <joint name="FL_upright_joint" type="revolute">
    <limit effort="100" lower="-0.5" upper="0.5" velocity="10"/>
    <axis xyz="0 0 1"/>
    <parent link="base_link"/>
    <child link="FL_upright"/>
    <origin rpy="0 0 0" xyz="0 0.1525 0"/>
  </joint>
  <link name="FL_upright">
    <inertial>
      <mass value="0.270"/>
      <origin rpy="0 0 0" xyz="0 0 0"/>
      <inertia ixx="2.632e-4" ixy="0" ixz="0" iyy="2.632e-4" iyz="0" izz="1.62e-4"/>
    </inertial>
    <visual>
      <origin xyz="0 0 0"/>
      <geometry>
        <box size="0.1 0.05 0.15"/>
      </geometry>
      <material name="Green"/>
    </visual>
    <!--collision>
            <origin xyz="0 0 0" />
            <geometry>
                <box size="0.1 0.05 0.15" />
            </geometry>
        </collision-->
  </link>
  <joint name="FL_wheel_joint" type="continuous">
    <axis xyz="0 1 0"/>
    <parent link="FL_upright"/>
    <child link="FL_wheel"/>
    <origin rpy="0 0 0" xyz="0 0.0725 0"/>
  </joint>
  <link name="FL_wheel">
    <inertial>
      <mass value="0.270"/>
      <origin rpy="0 0 0" xyz="0 0 0"/>
      <inertia ixx="2.632e-4" ixy="0" ixz="0" iyy="2.632e-4" iyz="0" izz="1.62e-4"/>
    </inertial>
    <visual>
      <origin rpy="0 0 1.57079633" xyz="0 0 0"/>
      <geometry>
        <mesh filename="package://quad_description/meshes/Tyre_13x5-6.STL"/>
      </geometry>
      <material name="Black"/>
    </visual>
    <collision>
      <origin rpy="1.57079633 0 0" xyz="0 0 0"/>
      <geometry>
        <cylinder length="0.122" radius="0.173"/>
      </geometry>
    </collision>
  </link>
  <gazebo reference="FL_wheel">
    <material>Gazebo/Black</material>
  </gazebo>
  <joint name="FR_upright_joint" type="revolute">
    <limit effort="100" lower="-0.5" upper="0.5" velocity="10"/>
    <axis xyz="0 0 1"/>
    <parent link="base_link"/>
    <child link="FR_upright"/>
    <origin rpy="0 0 0" xyz="0 -0.1525 0"/>
  </joint>
  <link name="FR_upright">
    <inertial>
      <mass value="0.270"/>
      <origin rpy="0 0 0" xyz="0 0 0"/>
      <inertia ixx="2.632e-4" ixy="0" ixz="0" iyy="2.632e-4" iyz="0" izz="1.62e-4"/>
    </inertial>
    <visual>
      <origin xyz="0 0 0"/>
      <geometry>
        <box size="0.1 0.05 0.15"/>
      </geometry>
      <material name="Green"/>
    </visual>
    <!--collision>
            <origin xyz="0 0 0" />
            <geometry>
                <box size="0.1 0.05 0.15" />
            </geometry>
        </collision-->
  </link>
  <joint name="FR_wheel_joint" type="continuous">
    <axis xyz="0 1 0"/>
    <parent link="FR_upright"/>
    <child link="FR_wheel"/>
    <origin rpy="0 0 0" xyz="0 -0.0725 0"/>
  </joint>
  <link name="FR_wheel">
    <inertial>
      <mass value="0.270"/>
      <origin rpy="0 0 0" xyz="0 0 0"/>
      <inertia ixx="2.632e-4" ixy="0" ixz="0" iyy="2.632e-4" iyz="0" izz="1.62e-4"/>
    </inertial>
    <visual>
      <origin rpy="0 0 1.57079633" xyz="0 0 0"/>
      <geometry>
        <mesh filename="package://quad_description/meshes/Tyre_13x5-6.STL"/>
      </geometry>
      <material name="Black"/>
    </visual>
    <collision>
      <origin rpy="1.57079633 0 0" xyz="0 0 0"/>
      <geometry>
        <cylinder length="0.122" radius="0.173"/>
      </geometry>
    </collision>
  </link>
  <gazebo reference="FR_wheel">
    <material>Gazebo/Black</material>
  </gazebo>
  <transmission name="FR_steering_trans">
    <type>transmission_interface/SimpleTransmission</type>
    <joint name="FR_upright_joint">
      <hardwareInterface>hardware_interface/EffortJointInterface</hardwareInterface>
    </joint>
    <actuator name="FR_steering_act">
      <mechanicalReduction>1</mechanicalReduction>
    </actuator>
  </transmission>
  <transmission name="FL_steering_trans">
    <type>transmission_interface/SimpleTransmission</type>
    <joint name="FL_upright_joint">
      <hardwareInterface>hardware_interface/EffortJointInterface</hardwareInterface>
    </joint>
    <actuator name="FL_steering_act">
      <mechanicalReduction>1</mechanicalReduction>
    </actuator>
  </transmission>
  <transmission name="RR_wheel_axle_trans">
    <type>transmission_interface/SimpleTransmission</type>
    <joint name="RR_wheel_joint">
      <hardwareInterface>hardware_interface/VelocityJointInterface</hardwareInterface>
    </joint>
    <actuator name="RR_wheel_axle_act">
      <mechanicalReduction>1</mechanicalReduction>
    </actuator>
  </transmission>
  <transmission name="RL_wheel_axle_trans">
    <type>transmission_interface/SimpleTransmission</type>
    <joint name="RL_wheel_joint">
      <hardwareInterface>hardware_interface/VelocityJointInterface</hardwareInterface>
    </joint>
    <actuator name="RL_wheel_axle_act">
      <mechanicalReduction>1</mechanicalReduction>
    </actuator>
  </transmission>
  <transmission name="FR_wheel_axle_trans">
    <type>transmission_interface/SimpleTransmission</type>
    <joint name="FR_wheel_joint">
      <hardwareInterface>hardware_interface/VelocityJointInterface</hardwareInterface>
    </joint>
    <actuator name="FR_wheel_axle_act">
      <mechanicalReduction>1</mechanicalReduction>
    </actuator>
  </transmission>
  <transmission name="FL_wheel_axle_trans">
    <type>transmission_interface/SimpleTransmission</type>
    <joint name="FL_wheel_joint">
      <hardwareInterface>hardware_interface/VelocityJointInterface</hardwareInterface>
    </joint>
    <actuator name="FL_wheel_axle_act">
      <mechanicalReduction>1</mechanicalReduction>
    </actuator>
  </transmission>
  <!--hokuyo_utm30lx_model name="hokuyo_laser" parent="base_link">
     <origin xyz="+0.222 0 0.003" rpy="0 0 0" />
    </hokuyo_utm30lx_model-->
  <joint name="hokuyo_base_joint" type="fixed">
    <!-- FRONT MOUNT  -->
    <!-- origin xyz="0.29 0 0.1" -->
    <!-- TOP MOUNT -->
    <!-- origin xyz="0.0 0.0 0.325"-->
    <origin rpy="0 0 0" xyz="+0.222 0 0.003"/>
    <parent link="base_link"/>
    <child link="hokuyo_base_link"/>
  </joint>
  <link name="hokuyo_base_link">
    <visual>
      <origin rpy="0 0 0" xyz="0 0 0"/>
      <geometry>
        <mesh filename="package://robotnik_sensors/meshes/hokuyo_utm_30lx.dae"/>
      </geometry>
    </visual>
    <inertial>
      <mass value="1e-5"/>
      <origin rpy="0 0 0" xyz="0 0 0"/>
      <inertia ixx="1e-6" ixy="0" ixz="0" iyy="1e-6" iyz="0" izz="1e-6"/>
    </inertial>
  </link>
  <link name="hokuyo_link">
	</link>
  <joint name="hokuyo_joint" type="fixed">
    <parent link="hokuyo_base_link"/>
    <child link="hokuyo_link"/>
    <origin rpy="0 0 0" xyz="0.00 0 0.055"/>
  </joint>
  <gazebo reference="hokuyo_link">
    <sensor name="hokuyo_sensor" type="ray">
      <pose>0 0 0 0 0 0</pose>
      <visualize>false</visualize>
      <update_rate>30</update_rate>
      <ray>
        <scan>
          <horizontal>
            <samples>1081</samples>
            <resolution>1</resolution>
            <min_angle>-1.57</min_angle>
            <max_angle>1.57</max_angle>
          </horizontal>
        </scan>
        <range>
          <min>0.10</min>
          <max>30.0</max>
          <resolution>0.01</resolution>
        </range>
        <noise>
          <type>gaussian</type>
          <mean>0.0</mean>
          <stddev>0.01</stddev>
        </noise>
      </ray>
      <plugin filename="libgazebo_ros_laser.so" name="hokuyo_controller">
        <topicName>front_laser/scan</topicName>
        <frameName>/hokuyo_link</frameName>
      </plugin>
    </sensor>
  </gazebo>
  <!-- ANTENNA GPS -->
  <joint name="gps_joint" type="fixed">
    <axis xyz="0 1 0"/>
    <origin rpy="0 0 0" xyz="-0.15 0 0.5"/>
    <parent link="base_link"/>
    <child link="gps_base_link"/>
  </joint>
  <link name="gps_base_link">
    <inertial>
      <mass value="0.001"/>
      <origin rpy="0 0 0" xyz="0 0 0"/>
      <inertia ixx="0.0001" ixy="0" ixz="0" iyy="0.000001" iyz="0" izz="0.0001"/>
    </inertial>
    <visual>
      <origin rpy="0 0 0" xyz="0 0 0"/>
      <material name="gps_color">
        <color rgba="1 1 1 1"/>
      </material>
      <geometry>
        <mesh filename="package://robotnik_sensors/meshes/antenna_3GO16.stl" scale="1.0 1.0 1.0"/>
      </geometry>
    </visual>
    <collision>
      <origin rpy="0 0 0" xyz="0 0 0"/>
      <geometry>
        <mesh filename="package://robotnik_sensors/meshes/antenna_3GO16.stl" scale="1.0 1.0 1.0"/>
      </geometry>
    </collision>
  </link>
  <gazebo reference="gps_base_link">
    <material>Gazebo/White</material>
    <gravity>true</gravity>
  </gazebo>
  <gazebo>
    <plugin filename="libhector_gazebo_ros_gps.so" name="gps_controller">
      <alwaysOn>1</alwaysOn>
      <updateRate>5</updateRate>
      <bodyName>gps_base_link</bodyName>
      <!-- must be the link of the gps device, not the base_link or base_footprint -->
      <frameId>/gps_base_link</frameId>
      <topicName>fix</topicName>
      <!-- Robotnik position at Fuente del Jarro -->
      <referenceLatitude>39.5080331</referenceLatitude>
      <referenceLongitude>-0.4619816</referenceLongitude>
      <!-- To set heading in ENU orientation (degrees) -->
      <referenceHeading>90</referenceHeading>
      <velocityTopicName>fix_velocity</velocityTopicName>
      <drift>0.0 0.0 0.0</drift>
      <!--<drift>0.0001 0.0001 0.0001</drift>-->
      <!--<drift>0.3 0.3 0.3</drift>-->
      <gaussianNoise>0.1 0.1 0.1</gaussianNoise>
      <!--<gaussianNoise>0.00001 0.00001 0.00001</gaussianNoise>-->
      <velocityDrift>0.00001 0.00001 0.00001</velocityDrift>
      <!--<velocityGaussianNoise>0.1 0.1 0.1</velocityGaussianNoise>-->
      <velocityGaussianNoise>0.00001 0.00001 0.00001</velocityGaussianNoise>
    </plugin>
  </gazebo>
  <!--generic_camera_model name="web_camera" parent="base_link">
     <origin xyz="0 0 0.01" rpy="0 0 0" />
  	</generic_camera_model-->
</robot>

