<?xml version="1.0" ?>
<!-- =================================================================================== -->
<!-- |    This document was autogenerated by xacro from quad.xacro                     | -->
<!-- |    EDITING THIS FILE BY HAND IS NOT RECOMMENDED                                 | -->
<!-- =================================================================================== -->
<robot name="quad" xmlns:xacro="http://www.ros.org/wiki/xacro">
  <!-- Physical Material Macros -->
  <material name="Red">
    <color rgba="1.0 0 0 1.0"/>
  </material>
  <material name="Green">
    <color rgba="0 1.0 0 1.0"/>
  </material>
  <material name="Blue">
    <color rgba="0 0 1.0 0.5"/>
  </material>
  <material name="Black">
    <color rgba="0 0 0 1.0"/>
  </material>
  <material name="Aqua">
    <color rgba="0 255 255 1.0"/>
  </material>
  <!-- base_link must have geometry so that its axes can be displayed in rviz. -->
  <!-- Chassis -->
  <link name="base_link">
    <visual>
      <origin rpy="0 0 0" xyz="-0.3535 0 0.173"/>
      <geometry>
        <box size="0.707 0.05 0.05"/>
      </geometry>
      <material name="Blue"/>
    </visual>
    <collision>
      <origin rpy="0 0 0" xyz="0 0 0"/>
      <geometry>
        <box size="-0.3535 0.05 0.05"/>
      </geometry>
    </collision>
  </link>
  <joint name="RL_wheel_joint" type="continuous">
    <axis xyz="0 1 0"/>
    <parent link="base_link"/>
    <child link="RL_wheel"/>
    <origin rpy="0 0 0" xyz="-0.707 0.24 0.173"/>
  </joint>
  <link name="RL_wheel">
    <visual>
      <origin rpy="0 0 1.57079633" xyz="0 0 0"/>
      <geometry>
        <mesh filename="package://quad_description/meshes/Tyre_13x5-6_3.STL"/>
      </geometry>
      <material name="Black"/>
    </visual>
    <collision>
      <origin rpy="0 0 0" xyz="0 0 0"/>
      <geometry>
        <mesh filename="package://quad_description/meshes/Tyre_13x5-6_3.STL"/>
      </geometry>
    </collision>
  </link>
  <joint name="RR_wheel_joint" type="continuous">
    <axis xyz="0 1 0"/>
    <parent link="base_link"/>
    <child link="RR_wheel"/>
    <origin rpy="0 0 0" xyz="-0.707 -0.24 0.173"/>
  </joint>
  <link name="RR_wheel">
    <visual>
      <origin rpy="0 0 1.57079633" xyz="0 0 0"/>
      <geometry>
        <mesh filename="package://quad_description/meshes/Tyre_13x5-6_3.STL"/>
      </geometry>
      <material name="Black"/>
    </visual>
    <collision>
      <origin rpy="0 0 0" xyz="0 0 0"/>
      <geometry>
        <mesh filename="package://quad_description/meshes/Tyre_13x5-6_3.STL"/>
      </geometry>
    </collision>
  </link>
  <joint name="FL_upright_joint" type="revolute">
    <limit effort="100" lower="-0.5" upper="0.5" velocity="10"/>
    <axis xyz="0 0 1"/>
    <parent link="base_link"/>
    <child link="FL_upright"/>
    <origin rpy="0 0 0" xyz="0 0.1525 0.173"/>
  </joint>
  <link name="FL_upright">
    <visual>
      <origin xyz="0 0 0"/>
      <geometry>
        <box size="0.1 0.05 0.15"/>
      </geometry>
      <material name="Green"/>
    </visual>
    <collision>
      <origin xyz="0 0 0"/>
      <geometry>
        <box size="0.1 0.05 0.15"/>
      </geometry>
    </collision>
  </link>
  <joint name="FL_wheel_joint" type="continuous">
    <axis xyz="0 1 0"/>
    <parent link="FL_upright"/>
    <child link="FL_wheel"/>
    <origin rpy="0 0 0" xyz="0 0.0725 0"/>
  </joint>
  <link name="FL_wheel">
    <visual>
      <origin rpy="0 0 1.57079633" xyz="0 0 0"/>
      <geometry>
        <mesh filename="package://quad_description/meshes/Tyre_13x5-6_3.STL"/>
      </geometry>
      <material name="Black"/>
    </visual>
    <collision>
      <origin rpy="0 0 0" xyz="0 0 0"/>
      <geometry>
        <mesh filename="package://quad_description/meshes/Tyre_13x5-6_3.STL"/>
      </geometry>
    </collision>
  </link>
  <joint name="FR_upright_joint" type="revolute">
    <limit effort="100" lower="-0.5" upper="0.5" velocity="10"/>
    <axis xyz="0 0 1"/>
    <parent link="base_link"/>
    <child link="FR_upright"/>
    <origin rpy="0 0 0" xyz="0 -0.1525 0.173"/>
  </joint>
  <link name="FR_upright">
    <visual>
      <origin xyz="0 0 0"/>
      <geometry>
        <box size="0.1 0.05 0.15"/>
      </geometry>
      <material name="Green"/>
    </visual>
    <collision>
      <origin xyz="0 0 0"/>
      <geometry>
        <box size="0.1 0.05 0.15"/>
      </geometry>
    </collision>
  </link>
  <joint name="FR_wheel_joint" type="continuous">
    <axis xyz="0 1 0"/>
    <parent link="FR_upright"/>
    <child link="FR_wheel"/>
    <origin rpy="0 0 0" xyz="0 -0.0725 0"/>
  </joint>
  <link name="FR_wheel">
    <visual>
      <origin rpy="0 0 1.57079633" xyz="0 0 0"/>
      <geometry>
        <mesh filename="package://quad_description/meshes/Tyre_13x5-6_3.STL"/>
      </geometry>
      <material name="Black"/>
    </visual>
    <collision>
      <origin rpy="0 0 0" xyz="0 0 0"/>
      <geometry>
        <mesh filename="package://quad_description/meshes/Tyre_13x5-6_3.STL"/>
      </geometry>
    </collision>
  </link>
  <joint name="hokuyo_laser_joint" type="fixed">
    <origin rpy="0 0 0" xyz="+0.222 0 0.176"/>
    <parent link="base_link"/>
    <child link="hokuyo_laser_frame"/>
  </joint>
  <link name="hokuyo_laser_frame">
    <inertial>
      <mass value="0.270"/>
      <origin rpy="0 0 0" xyz="0 0 0"/>
      <inertia ixx="2.632e-4" ixy="0" ixz="0" iyy="2.632e-4" iyz="0" izz="1.62e-4"/>
    </inertial>
    <visual>
      <origin rpy="0 0 0" xyz="0 0 0"/>
      <geometry>
        <mesh filename="package://hector_sensors_description/meshes/hokuyo_utm30lx/hokuyo_utm_30lx.dae"/>
      </geometry>
    </visual>
    <collision>
      <origin rpy="0 0 0" xyz="0 0 -0.0115"/>
      <geometry>
        <box size="0.058 0.058 0.087"/>
        <!--<mesh filename="package://hector_sensors_description/meshes/hokuyo_utm30lx/hokuyo_utm_30lx.stl"/>-->
      </geometry>
    </collision>
  </link>
</robot>

